[2025-07-31T03:23:53.847+0000] {taskinstance.py:1956} INFO - Dependencies all met for dep_context=non-requeueable deps ti=<TaskInstance: dataproc_gcs_to_bq.create_cluster manual__2025-07-31T03:23:51.241963+00:00 [queued]>
[2025-07-31T03:23:53.858+0000] {taskinstance.py:1956} INFO - Dependencies all met for dep_context=requeueable deps ti=<TaskInstance: dataproc_gcs_to_bq.create_cluster manual__2025-07-31T03:23:51.241963+00:00 [queued]>
[2025-07-31T03:23:53.859+0000] {taskinstance.py:2170} INFO - Starting attempt 1 of 1
[2025-07-31T03:23:53.879+0000] {taskinstance.py:2191} INFO - Executing <Task(DataprocCreateClusterOperator): create_cluster> on 2025-07-31 03:23:51.241963+00:00
[2025-07-31T03:23:53.892+0000] {standard_task_runner.py:60} INFO - Started process 1296 to run task
[2025-07-31T03:23:53.900+0000] {standard_task_runner.py:87} INFO - Running: ['***', 'tasks', 'run', 'dataproc_gcs_to_bq', 'create_cluster', 'manual__2025-07-31T03:23:51.241963+00:00', '--job-id', '15', '--raw', '--subdir', 'DAGS_FOLDER/dataproc_gcs_to_bq.py', '--cfg-path', '/tmp/tmp0c_olp7n']
[2025-07-31T03:23:53.903+0000] {standard_task_runner.py:88} INFO - Job 15: Subtask create_cluster
[2025-07-31T03:23:53.992+0000] {task_command.py:423} INFO - Running <TaskInstance: dataproc_gcs_to_bq.create_cluster manual__2025-07-31T03:23:51.241963+00:00 [running]> on host e63302d63f25
[2025-07-31T03:23:54.109+0000] {taskinstance.py:2480} INFO - Exporting env vars: AIRFLOW_CTX_DAG_OWNER='***' AIRFLOW_CTX_DAG_ID='dataproc_gcs_to_bq' AIRFLOW_CTX_TASK_ID='create_cluster' AIRFLOW_CTX_EXECUTION_DATE='2025-07-31T03:23:51.241963+00:00' AIRFLOW_CTX_TRY_NUMBER='1' AIRFLOW_CTX_DAG_RUN_ID='manual__2025-07-31T03:23:51.241963+00:00'
[2025-07-31T03:23:54.112+0000] {dataproc.py:722} INFO - Creating cluster: gcs-to-bq-cluster
[2025-07-31T03:23:54.140+0000] {connection.py:234} WARNING - Connection schemes (type: google_cloud_platform) shall not contain '_' according to RFC3986.
[2025-07-31T03:23:54.156+0000] {base.py:83} INFO - Using connection ID 'google_cloud_default' for task execution.
[2025-07-31T03:23:55.410+0000] {taskinstance.py:2698} ERROR - Task failed with exception
Traceback (most recent call last):
  File "/home/airflow/.local/lib/python3.8/site-packages/google/api_core/grpc_helpers.py", line 79, in error_remapped_callable
    return callable_(*args, **kwargs)
  File "/home/airflow/.local/lib/python3.8/site-packages/grpc/_channel.py", line 1160, in __call__
    return _end_unary_response_blocking(state, call, False, None)
  File "/home/airflow/.local/lib/python3.8/site-packages/grpc/_channel.py", line 1003, in _end_unary_response_blocking
    raise _InactiveRpcError(state)  # pytype: disable=not-instantiable
grpc._channel._InactiveRpcError: <_InactiveRpcError of RPC that terminated with:
	status = StatusCode.PERMISSION_DENIED
	details = "Cloud Dataproc API has not been used in project target-de before or it is disabled. Enable it by visiting https://console.developers.google.com/apis/api/dataproc.googleapis.com/overview?project=target-de then retry. If you enabled this API recently, wait a few minutes for the action to propagate to our systems and retry."
	debug_error_string = "UNKNOWN:Error received from peer ipv4:192.178.220.95:443 {created_time:"2025-07-31T03:23:55.393556903+00:00", grpc_status:7, grpc_message:"Cloud Dataproc API has not been used in project target-de before or it is disabled. Enable it by visiting https://console.developers.google.com/apis/api/dataproc.googleapis.com/overview?project=target-de then retry. If you enabled this API recently, wait a few minutes for the action to propagate to our systems and retry."}"
>

The above exception was the direct cause of the following exception:

Traceback (most recent call last):
  File "/home/airflow/.local/lib/python3.8/site-packages/airflow/models/taskinstance.py", line 433, in _execute_task
    result = execute_callable(context=context, **execute_callable_kwargs)
  File "/home/airflow/.local/lib/python3.8/site-packages/airflow/providers/google/cloud/operators/dataproc.py", line 736, in execute
    operation = self._create_cluster(hook)
  File "/home/airflow/.local/lib/python3.8/site-packages/airflow/providers/google/cloud/operators/dataproc.py", line 652, in _create_cluster
    return hook.create_cluster(
  File "/home/airflow/.local/lib/python3.8/site-packages/airflow/providers/google/common/hooks/base_google.py", line 477, in inner_wrapper
    return func(self, *args, **kwargs)
  File "/home/airflow/.local/lib/python3.8/site-packages/airflow/providers/google/cloud/hooks/dataproc.py", line 325, in create_cluster
    result = client.create_cluster(
  File "/home/airflow/.local/lib/python3.8/site-packages/google/cloud/dataproc_v1/services/cluster_controller/client.py", line 632, in create_cluster
    response = rpc(
  File "/home/airflow/.local/lib/python3.8/site-packages/google/api_core/gapic_v1/method.py", line 131, in __call__
    return wrapped_func(*args, **kwargs)
  File "/home/airflow/.local/lib/python3.8/site-packages/google/api_core/retry.py", line 372, in retry_wrapped_func
    return retry_target(
  File "/home/airflow/.local/lib/python3.8/site-packages/google/api_core/retry.py", line 207, in retry_target
    result = target()
  File "/home/airflow/.local/lib/python3.8/site-packages/google/api_core/timeout.py", line 120, in func_with_timeout
    return func(*args, **kwargs)
  File "/home/airflow/.local/lib/python3.8/site-packages/google/api_core/grpc_helpers.py", line 81, in error_remapped_callable
    raise exceptions.from_grpc_error(exc) from exc
google.api_core.exceptions.PermissionDenied: 403 Cloud Dataproc API has not been used in project target-de before or it is disabled. Enable it by visiting https://console.developers.google.com/apis/api/dataproc.googleapis.com/overview?project=target-de then retry. If you enabled this API recently, wait a few minutes for the action to propagate to our systems and retry. [reason: "SERVICE_DISABLED"
domain: "googleapis.com"
metadata {
  key: "service"
  value: "dataproc.googleapis.com"
}
metadata {
  key: "serviceTitle"
  value: "Cloud Dataproc API"
}
metadata {
  key: "containerInfo"
  value: "target-de"
}
metadata {
  key: "consumer"
  value: "projects/target-de"
}
metadata {
  key: "activationUrl"
  value: "https://console.developers.google.com/apis/api/dataproc.googleapis.com/overview?project=target-de"
}
, locale: "en-US"
message: "Cloud Dataproc API has not been used in project target-de before or it is disabled. Enable it by visiting https://console.developers.google.com/apis/api/dataproc.googleapis.com/overview?project=target-de then retry. If you enabled this API recently, wait a few minutes for the action to propagate to our systems and retry."
, links {
  description: "Google developers console API activation"
  url: "https://console.developers.google.com/apis/api/dataproc.googleapis.com/overview?project=target-de"
}
]
[2025-07-31T03:23:55.457+0000] {taskinstance.py:1138} INFO - Marking task as FAILED. dag_id=dataproc_gcs_to_bq, task_id=create_cluster, execution_date=20250731T032351, start_date=20250731T032353, end_date=20250731T032355
[2025-07-31T03:23:55.492+0000] {standard_task_runner.py:107} ERROR - Failed to execute job 15 for task create_cluster (403 Cloud Dataproc API has not been used in project target-de before or it is disabled. Enable it by visiting https://console.developers.google.com/apis/api/dataproc.googleapis.com/overview?project=target-de then retry. If you enabled this API recently, wait a few minutes for the action to propagate to our systems and retry. [reason: "SERVICE_DISABLED"
domain: "googleapis.com"
metadata {
  key: "service"
  value: "dataproc.googleapis.com"
}
metadata {
  key: "serviceTitle"
  value: "Cloud Dataproc API"
}
metadata {
  key: "containerInfo"
  value: "target-de"
}
metadata {
  key: "consumer"
  value: "projects/target-de"
}
metadata {
  key: "activationUrl"
  value: "https://console.developers.google.com/apis/api/dataproc.googleapis.com/overview?project=target-de"
}
, locale: "en-US"
message: "Cloud Dataproc API has not been used in project target-de before or it is disabled. Enable it by visiting https://console.developers.google.com/apis/api/dataproc.googleapis.com/overview?project=target-de then retry. If you enabled this API recently, wait a few minutes for the action to propagate to our systems and retry."
, links {
  description: "Google developers console API activation"
  url: "https://console.developers.google.com/apis/api/dataproc.googleapis.com/overview?project=target-de"
}
]; 1296)
[2025-07-31T03:23:55.531+0000] {local_task_job_runner.py:234} INFO - Task exited with return code 1
[2025-07-31T03:23:55.604+0000] {taskinstance.py:3280} INFO - 0 downstream tasks scheduled from follow-on schedule check
