[2025-07-31T03:33:04.924+0000] {taskinstance.py:1956} INFO - Dependencies all met for dep_context=non-requeueable deps ti=<TaskInstance: dataproc_gcs_to_bq.create_cluster manual__2025-07-31T03:33:02.636372+00:00 [queued]>
[2025-07-31T03:33:04.938+0000] {taskinstance.py:1956} INFO - Dependencies all met for dep_context=requeueable deps ti=<TaskInstance: dataproc_gcs_to_bq.create_cluster manual__2025-07-31T03:33:02.636372+00:00 [queued]>
[2025-07-31T03:33:04.939+0000] {taskinstance.py:2170} INFO - Starting attempt 1 of 1
[2025-07-31T03:33:04.962+0000] {taskinstance.py:2191} INFO - Executing <Task(DataprocCreateClusterOperator): create_cluster> on 2025-07-31 03:33:02.636372+00:00
[2025-07-31T03:33:04.984+0000] {standard_task_runner.py:60} INFO - Started process 1545 to run task
[2025-07-31T03:33:04.995+0000] {standard_task_runner.py:87} INFO - Running: ['***', 'tasks', 'run', 'dataproc_gcs_to_bq', 'create_cluster', 'manual__2025-07-31T03:33:02.636372+00:00', '--job-id', '25', '--raw', '--subdir', 'DAGS_FOLDER/dataproc_gcs_to_bq.py', '--cfg-path', '/tmp/tmp0syqapmh']
[2025-07-31T03:33:05.001+0000] {standard_task_runner.py:88} INFO - Job 25: Subtask create_cluster
[2025-07-31T03:33:05.112+0000] {task_command.py:423} INFO - Running <TaskInstance: dataproc_gcs_to_bq.create_cluster manual__2025-07-31T03:33:02.636372+00:00 [running]> on host e63302d63f25
[2025-07-31T03:33:05.221+0000] {taskinstance.py:2480} INFO - Exporting env vars: AIRFLOW_CTX_DAG_OWNER='***' AIRFLOW_CTX_DAG_ID='dataproc_gcs_to_bq' AIRFLOW_CTX_TASK_ID='create_cluster' AIRFLOW_CTX_EXECUTION_DATE='2025-07-31T03:33:02.636372+00:00' AIRFLOW_CTX_TRY_NUMBER='1' AIRFLOW_CTX_DAG_RUN_ID='manual__2025-07-31T03:33:02.636372+00:00'
[2025-07-31T03:33:05.224+0000] {dataproc.py:722} INFO - Creating cluster: gcs-to-bq-cluster
[2025-07-31T03:33:05.236+0000] {connection.py:234} WARNING - Connection schemes (type: google_cloud_platform) shall not contain '_' according to RFC3986.
[2025-07-31T03:33:05.244+0000] {base.py:83} INFO - Using connection ID 'google_cloud_default' for task execution.
[2025-07-31T03:33:07.880+0000] {taskinstance.py:2698} ERROR - Task failed with exception
Traceback (most recent call last):
  File "/home/airflow/.local/lib/python3.8/site-packages/google/api_core/grpc_helpers.py", line 79, in error_remapped_callable
    return callable_(*args, **kwargs)
  File "/home/airflow/.local/lib/python3.8/site-packages/grpc/_channel.py", line 1160, in __call__
    return _end_unary_response_blocking(state, call, False, None)
  File "/home/airflow/.local/lib/python3.8/site-packages/grpc/_channel.py", line 1003, in _end_unary_response_blocking
    raise _InactiveRpcError(state)  # pytype: disable=not-instantiable
grpc._channel._InactiveRpcError: <_InactiveRpcError of RPC that terminated with:
	status = StatusCode.INVALID_ARGUMENT
	details = "Multiple validation errors:
 - Permissions are missing for the default service account '267262649432-compute@developer.gserviceaccount.com', missing permissions: [storage.buckets.get] on the project 'projects/target-de'. This usually happens when a custom resource (ex: custom staging bucket) or a user-managed VM Service account has been provided and the default/user-managed service account hasn't been granted enough permissions on the resource. See https://cloud.google.com/dataproc/docs/concepts/configuring-clusters/service-accounts#VM_service_account.
 - User not authorized to act as service account '267262649432-compute@developer.gserviceaccount.com'. To act as a service account, user must have one of [Owner, Editor, Service Account User] roles. See https://cloud.google.com/iam/docs/understanding-service-accounts for additional details."
	debug_error_string = "UNKNOWN:Error received from peer ipv4:173.194.208.95:443 {created_time:"2025-07-31T03:33:07.878892327+00:00", grpc_status:3, grpc_message:"Multiple validation errors:\n - Permissions are missing for the default service account \'267262649432-compute@developer.gserviceaccount.com\', missing permissions: [storage.buckets.get] on the project \'projects/target-de\'. This usually happens when a custom resource (ex: custom staging bucket) or a user-managed VM Service account has been provided and the default/user-managed service account hasn\'t been granted enough permissions on the resource. See https://cloud.google.com/dataproc/docs/concepts/configuring-clusters/service-accounts#VM_service_account.\n - User not authorized to act as service account \'267262649432-compute@developer.gserviceaccount.com\'. To act as a service account, user must have one of [Owner, Editor, Service Account User] roles. See https://cloud.google.com/iam/docs/understanding-service-accounts for additional details."}"
>

The above exception was the direct cause of the following exception:

Traceback (most recent call last):
  File "/home/airflow/.local/lib/python3.8/site-packages/airflow/models/taskinstance.py", line 433, in _execute_task
    result = execute_callable(context=context, **execute_callable_kwargs)
  File "/home/airflow/.local/lib/python3.8/site-packages/airflow/providers/google/cloud/operators/dataproc.py", line 736, in execute
    operation = self._create_cluster(hook)
  File "/home/airflow/.local/lib/python3.8/site-packages/airflow/providers/google/cloud/operators/dataproc.py", line 652, in _create_cluster
    return hook.create_cluster(
  File "/home/airflow/.local/lib/python3.8/site-packages/airflow/providers/google/common/hooks/base_google.py", line 477, in inner_wrapper
    return func(self, *args, **kwargs)
  File "/home/airflow/.local/lib/python3.8/site-packages/airflow/providers/google/cloud/hooks/dataproc.py", line 325, in create_cluster
    result = client.create_cluster(
  File "/home/airflow/.local/lib/python3.8/site-packages/google/cloud/dataproc_v1/services/cluster_controller/client.py", line 632, in create_cluster
    response = rpc(
  File "/home/airflow/.local/lib/python3.8/site-packages/google/api_core/gapic_v1/method.py", line 131, in __call__
    return wrapped_func(*args, **kwargs)
  File "/home/airflow/.local/lib/python3.8/site-packages/google/api_core/retry.py", line 372, in retry_wrapped_func
    return retry_target(
  File "/home/airflow/.local/lib/python3.8/site-packages/google/api_core/retry.py", line 207, in retry_target
    result = target()
  File "/home/airflow/.local/lib/python3.8/site-packages/google/api_core/timeout.py", line 120, in func_with_timeout
    return func(*args, **kwargs)
  File "/home/airflow/.local/lib/python3.8/site-packages/google/api_core/grpc_helpers.py", line 81, in error_remapped_callable
    raise exceptions.from_grpc_error(exc) from exc
google.api_core.exceptions.InvalidArgument: 400 Multiple validation errors:
 - Permissions are missing for the default service account '267262649432-compute@developer.gserviceaccount.com', missing permissions: [storage.buckets.get] on the project 'projects/target-de'. This usually happens when a custom resource (ex: custom staging bucket) or a user-managed VM Service account has been provided and the default/user-managed service account hasn't been granted enough permissions on the resource. See https://cloud.google.com/dataproc/docs/concepts/configuring-clusters/service-accounts#VM_service_account.
 - User not authorized to act as service account '267262649432-compute@developer.gserviceaccount.com'. To act as a service account, user must have one of [Owner, Editor, Service Account User] roles. See https://cloud.google.com/iam/docs/understanding-service-accounts for additional details.
[2025-07-31T03:33:07.893+0000] {taskinstance.py:1138} INFO - Marking task as FAILED. dag_id=dataproc_gcs_to_bq, task_id=create_cluster, execution_date=20250731T033302, start_date=20250731T033304, end_date=20250731T033307
[2025-07-31T03:33:07.916+0000] {standard_task_runner.py:107} ERROR - Failed to execute job 25 for task create_cluster (400 Multiple validation errors:
 - Permissions are missing for the default service account '267262649432-compute@developer.gserviceaccount.com', missing permissions: [storage.buckets.get] on the project 'projects/target-de'. This usually happens when a custom resource (ex: custom staging bucket) or a user-managed VM Service account has been provided and the default/user-managed service account hasn't been granted enough permissions on the resource. See https://cloud.google.com/dataproc/docs/concepts/configuring-clusters/service-accounts#VM_service_account.
 - User not authorized to act as service account '267262649432-compute@developer.gserviceaccount.com'. To act as a service account, user must have one of [Owner, Editor, Service Account User] roles. See https://cloud.google.com/iam/docs/understanding-service-accounts for additional details.; 1545)
[2025-07-31T03:33:07.942+0000] {local_task_job_runner.py:234} INFO - Task exited with return code 1
[2025-07-31T03:33:07.973+0000] {taskinstance.py:3280} INFO - 0 downstream tasks scheduled from follow-on schedule check
