[2025-07-31T03:23:57.934+0000] {taskinstance.py:1956} INFO - Dependencies all met for dep_context=non-requeueable deps ti=<TaskInstance: dataproc_gcs_to_bq.delete_cluster manual__2025-07-31T03:23:51.241963+00:00 [queued]>
[2025-07-31T03:23:57.951+0000] {taskinstance.py:1956} INFO - Dependencies all met for dep_context=requeueable deps ti=<TaskInstance: dataproc_gcs_to_bq.delete_cluster manual__2025-07-31T03:23:51.241963+00:00 [queued]>
[2025-07-31T03:23:57.954+0000] {taskinstance.py:2170} INFO - Starting attempt 1 of 1
[2025-07-31T03:23:57.978+0000] {taskinstance.py:2191} INFO - Executing <Task(DataprocDeleteClusterOperator): delete_cluster> on 2025-07-31 03:23:51.241963+00:00
[2025-07-31T03:23:57.989+0000] {standard_task_runner.py:60} INFO - Started process 1308 to run task
[2025-07-31T03:23:57.996+0000] {standard_task_runner.py:87} INFO - Running: ['***', 'tasks', 'run', 'dataproc_gcs_to_bq', 'delete_cluster', 'manual__2025-07-31T03:23:51.241963+00:00', '--job-id', '16', '--raw', '--subdir', 'DAGS_FOLDER/dataproc_gcs_to_bq.py', '--cfg-path', '/tmp/tmppqe6_5ad']
[2025-07-31T03:23:58.004+0000] {standard_task_runner.py:88} INFO - Job 16: Subtask delete_cluster
[2025-07-31T03:23:58.191+0000] {task_command.py:423} INFO - Running <TaskInstance: dataproc_gcs_to_bq.delete_cluster manual__2025-07-31T03:23:51.241963+00:00 [running]> on host e63302d63f25
[2025-07-31T03:23:58.375+0000] {taskinstance.py:2480} INFO - Exporting env vars: AIRFLOW_CTX_DAG_OWNER='***' AIRFLOW_CTX_DAG_ID='dataproc_gcs_to_bq' AIRFLOW_CTX_TASK_ID='delete_cluster' AIRFLOW_CTX_EXECUTION_DATE='2025-07-31T03:23:51.241963+00:00' AIRFLOW_CTX_TRY_NUMBER='1' AIRFLOW_CTX_DAG_RUN_ID='manual__2025-07-31T03:23:51.241963+00:00'
[2025-07-31T03:23:58.396+0000] {connection.py:234} WARNING - Connection schemes (type: google_cloud_platform) shall not contain '_' according to RFC3986.
[2025-07-31T03:23:58.415+0000] {base.py:83} INFO - Using connection ID 'google_cloud_default' for task execution.
[2025-07-31T03:23:58.416+0000] {dataproc.py:1047} INFO - Deleting cluster: gcs-to-bq-cluster
[2025-07-31T03:23:59.065+0000] {taskinstance.py:2698} ERROR - Task failed with exception
Traceback (most recent call last):
  File "/home/airflow/.local/lib/python3.8/site-packages/google/api_core/grpc_helpers.py", line 79, in error_remapped_callable
    return callable_(*args, **kwargs)
  File "/home/airflow/.local/lib/python3.8/site-packages/grpc/_channel.py", line 1160, in __call__
    return _end_unary_response_blocking(state, call, False, None)
  File "/home/airflow/.local/lib/python3.8/site-packages/grpc/_channel.py", line 1003, in _end_unary_response_blocking
    raise _InactiveRpcError(state)  # pytype: disable=not-instantiable
grpc._channel._InactiveRpcError: <_InactiveRpcError of RPC that terminated with:
	status = StatusCode.PERMISSION_DENIED
	details = "Cloud Dataproc API has not been used in project target-de before or it is disabled. Enable it by visiting https://console.developers.google.com/apis/api/dataproc.googleapis.com/overview?project=target-de then retry. If you enabled this API recently, wait a few minutes for the action to propagate to our systems and retry."
	debug_error_string = "UNKNOWN:Error received from peer ipv4:192.178.220.95:443 {grpc_message:"Cloud Dataproc API has not been used in project target-de before or it is disabled. Enable it by visiting https://console.developers.google.com/apis/api/dataproc.googleapis.com/overview?project=target-de then retry. If you enabled this API recently, wait a few minutes for the action to propagate to our systems and retry.", grpc_status:7, created_time:"2025-07-31T03:23:59.062770017+00:00"}"
>

The above exception was the direct cause of the following exception:

Traceback (most recent call last):
  File "/home/airflow/.local/lib/python3.8/site-packages/airflow/models/taskinstance.py", line 433, in _execute_task
    result = execute_callable(context=context, **execute_callable_kwargs)
  File "/home/airflow/.local/lib/python3.8/site-packages/airflow/providers/google/cloud/operators/dataproc.py", line 1014, in execute
    operation = self._delete_cluster(hook)
  File "/home/airflow/.local/lib/python3.8/site-packages/airflow/providers/google/cloud/operators/dataproc.py", line 1048, in _delete_cluster
    return hook.delete_cluster(
  File "/home/airflow/.local/lib/python3.8/site-packages/airflow/providers/google/common/hooks/base_google.py", line 477, in inner_wrapper
    return func(self, *args, **kwargs)
  File "/home/airflow/.local/lib/python3.8/site-packages/airflow/providers/google/cloud/hooks/dataproc.py", line 369, in delete_cluster
    result = client.delete_cluster(
  File "/home/airflow/.local/lib/python3.8/site-packages/google/cloud/dataproc_v1/services/cluster_controller/client.py", line 1221, in delete_cluster
    response = rpc(
  File "/home/airflow/.local/lib/python3.8/site-packages/google/api_core/gapic_v1/method.py", line 131, in __call__
    return wrapped_func(*args, **kwargs)
  File "/home/airflow/.local/lib/python3.8/site-packages/google/api_core/retry.py", line 372, in retry_wrapped_func
    return retry_target(
  File "/home/airflow/.local/lib/python3.8/site-packages/google/api_core/retry.py", line 207, in retry_target
    result = target()
  File "/home/airflow/.local/lib/python3.8/site-packages/google/api_core/timeout.py", line 120, in func_with_timeout
    return func(*args, **kwargs)
  File "/home/airflow/.local/lib/python3.8/site-packages/google/api_core/grpc_helpers.py", line 81, in error_remapped_callable
    raise exceptions.from_grpc_error(exc) from exc
google.api_core.exceptions.PermissionDenied: 403 Cloud Dataproc API has not been used in project target-de before or it is disabled. Enable it by visiting https://console.developers.google.com/apis/api/dataproc.googleapis.com/overview?project=target-de then retry. If you enabled this API recently, wait a few minutes for the action to propagate to our systems and retry. [reason: "SERVICE_DISABLED"
domain: "googleapis.com"
metadata {
  key: "service"
  value: "dataproc.googleapis.com"
}
metadata {
  key: "serviceTitle"
  value: "Cloud Dataproc API"
}
metadata {
  key: "containerInfo"
  value: "target-de"
}
metadata {
  key: "consumer"
  value: "projects/target-de"
}
metadata {
  key: "activationUrl"
  value: "https://console.developers.google.com/apis/api/dataproc.googleapis.com/overview?project=target-de"
}
, locale: "en-US"
message: "Cloud Dataproc API has not been used in project target-de before or it is disabled. Enable it by visiting https://console.developers.google.com/apis/api/dataproc.googleapis.com/overview?project=target-de then retry. If you enabled this API recently, wait a few minutes for the action to propagate to our systems and retry."
, links {
  description: "Google developers console API activation"
  url: "https://console.developers.google.com/apis/api/dataproc.googleapis.com/overview?project=target-de"
}
]
[2025-07-31T03:23:59.093+0000] {taskinstance.py:1138} INFO - Marking task as FAILED. dag_id=dataproc_gcs_to_bq, task_id=delete_cluster, execution_date=20250731T032351, start_date=20250731T032357, end_date=20250731T032359
[2025-07-31T03:23:59.119+0000] {standard_task_runner.py:107} ERROR - Failed to execute job 16 for task delete_cluster (403 Cloud Dataproc API has not been used in project target-de before or it is disabled. Enable it by visiting https://console.developers.google.com/apis/api/dataproc.googleapis.com/overview?project=target-de then retry. If you enabled this API recently, wait a few minutes for the action to propagate to our systems and retry. [reason: "SERVICE_DISABLED"
domain: "googleapis.com"
metadata {
  key: "service"
  value: "dataproc.googleapis.com"
}
metadata {
  key: "serviceTitle"
  value: "Cloud Dataproc API"
}
metadata {
  key: "containerInfo"
  value: "target-de"
}
metadata {
  key: "consumer"
  value: "projects/target-de"
}
metadata {
  key: "activationUrl"
  value: "https://console.developers.google.com/apis/api/dataproc.googleapis.com/overview?project=target-de"
}
, locale: "en-US"
message: "Cloud Dataproc API has not been used in project target-de before or it is disabled. Enable it by visiting https://console.developers.google.com/apis/api/dataproc.googleapis.com/overview?project=target-de then retry. If you enabled this API recently, wait a few minutes for the action to propagate to our systems and retry."
, links {
  description: "Google developers console API activation"
  url: "https://console.developers.google.com/apis/api/dataproc.googleapis.com/overview?project=target-de"
}
]; 1308)
[2025-07-31T03:23:59.167+0000] {local_task_job_runner.py:234} INFO - Task exited with return code 1
[2025-07-31T03:23:59.200+0000] {taskinstance.py:3280} INFO - 0 downstream tasks scheduled from follow-on schedule check
