[2025-07-31T02:31:01.628+0000] {taskinstance.py:1956} INFO - Dependencies all met for dep_context=non-requeueable deps ti=<TaskInstance: gcs_to_bq_dag.load_existing_bq_table manual__2025-07-31T02:30:50.641039+00:00 [queued]>
[2025-07-31T02:31:01.651+0000] {taskinstance.py:1956} INFO - Dependencies all met for dep_context=requeueable deps ti=<TaskInstance: gcs_to_bq_dag.load_existing_bq_table manual__2025-07-31T02:30:50.641039+00:00 [queued]>
[2025-07-31T02:31:01.653+0000] {taskinstance.py:2170} INFO - Starting attempt 1 of 1
[2025-07-31T02:31:01.684+0000] {taskinstance.py:2191} INFO - Executing <Task(GCSToBigQueryOperator): load_existing_bq_table> on 2025-07-31 02:30:50.641039+00:00
[2025-07-31T02:31:01.709+0000] {standard_task_runner.py:60} INFO - Started process 540 to run task
[2025-07-31T02:31:01.750+0000] {standard_task_runner.py:87} INFO - Running: ['***', 'tasks', 'run', 'gcs_to_bq_dag', 'load_existing_bq_table', 'manual__2025-07-31T02:30:50.641039+00:00', '--job-id', '11', '--raw', '--subdir', 'DAGS_FOLDER/gcs_to_bq_dag.py', '--cfg-path', '/tmp/tmpig7014sn']
[2025-07-31T02:31:01.758+0000] {standard_task_runner.py:88} INFO - Job 11: Subtask load_existing_bq_table
[2025-07-31T02:31:02.084+0000] {task_command.py:423} INFO - Running <TaskInstance: gcs_to_bq_dag.load_existing_bq_table manual__2025-07-31T02:30:50.641039+00:00 [running]> on host e63302d63f25
[2025-07-31T02:31:02.273+0000] {taskinstance.py:2480} INFO - Exporting env vars: AIRFLOW_CTX_DAG_OWNER='***' AIRFLOW_CTX_DAG_ID='gcs_to_bq_dag' AIRFLOW_CTX_TASK_ID='load_existing_bq_table' AIRFLOW_CTX_EXECUTION_DATE='2025-07-31T02:30:50.641039+00:00' AIRFLOW_CTX_TRY_NUMBER='1' AIRFLOW_CTX_DAG_RUN_ID='manual__2025-07-31T02:30:50.641039+00:00'
[2025-07-31T02:31:02.364+0000] {taskinstance.py:2698} ERROR - Task failed with exception
Traceback (most recent call last):
  File "/home/airflow/.local/lib/python3.8/site-packages/airflow/models/taskinstance.py", line 433, in _execute_task
    result = execute_callable(context=context, **execute_callable_kwargs)
  File "/home/airflow/.local/lib/python3.8/site-packages/airflow/providers/google/cloud/transfers/gcs_to_bigquery.py", line 322, in execute
    hook = BigQueryHook(
  File "/home/airflow/.local/lib/python3.8/site-packages/airflow/providers/google/cloud/hooks/bigquery.py", line 118, in __init__
    super().__init__(
  File "/home/airflow/.local/lib/python3.8/site-packages/airflow/providers/google/common/hooks/base_google.py", line 242, in __init__
    self.extras: dict = self.get_connection(self.gcp_conn_id).extra_dejson
  File "/home/airflow/.local/lib/python3.8/site-packages/airflow/hooks/base.py", line 82, in get_connection
    conn = Connection.get_connection_from_secrets(conn_id)
  File "/home/airflow/.local/lib/python3.8/site-packages/airflow/models/connection.py", line 479, in get_connection_from_secrets
    raise AirflowNotFoundException(f"The conn_id `{conn_id}` isn't defined")
airflow.exceptions.AirflowNotFoundException: The conn_id `google_cloud_default` isn't defined
[2025-07-31T02:31:02.386+0000] {taskinstance.py:1138} INFO - Marking task as FAILED. dag_id=gcs_to_bq_dag, task_id=load_existing_bq_table, execution_date=20250731T023050, start_date=20250731T023101, end_date=20250731T023102
[2025-07-31T02:31:02.511+0000] {standard_task_runner.py:107} ERROR - Failed to execute job 11 for task load_existing_bq_table (The conn_id `google_cloud_default` isn't defined; 540)
[2025-07-31T02:31:02.614+0000] {local_task_job_runner.py:234} INFO - Task exited with return code 1
[2025-07-31T02:31:02.848+0000] {taskinstance.py:3280} INFO - 0 downstream tasks scheduled from follow-on schedule check
